<?xml version="1.0" encoding="utf-8" ?>
<testsuites>
    <testsuite errors="1" failures="1" hostname="" name="MyTestSuite" skipped="0" tests="4" time="0.052" timestamp="2019-11-05T22:18:27.847276">
        <testcase classname="tests.test_simple1" file="tests/test_simple1.py" line="6" name="test_something1" time="0.001">
            <system-out>Test output 1
</system-out>
        </testcase>
        <testcase classname="tests.test_simple1" file="tests/test_simple1.py" line="10" name="test_something2" time="2.001">
            <failure message="assert False">def test_something2():
        print(&quot;Test output 2&quot;)
&gt;       assert False
E       assert False

tests/test_simple1.py:13: AssertionError</failure>
            <system-out>Test output 2
</system-out>
        </testcase>
        <testcase classname="tests.test_simple1" file="tests/test_simple1.py" line="14" name="test_something3" time="3.000">
            <error message="test setup failure">@pytest.fixture
    def badMethod():
&gt;       raise Exception(&quot;Test error&quot;)
E       Exception: Test error

tests/test_simple1.py:5: Exception</error>
        </testcase>
        <testcase classname="tests.test_simple2" file="tests/test_simple2.py" line="0" name="test_ok" time="0.000">
            <system-out>Test output
</system-out>
        </testcase>
    </testsuite>
</testsuites>